{
 "cells": [
  {
   "cell_type": "code",
   "execution_count": 2,
   "id": "48c88ff1",
   "metadata": {},
   "outputs": [
    {
     "name": "stdout",
     "output_type": "stream",
     "text": [
      "Defaulting to user installation because normal site-packages is not writeable\n",
      "Requirement already satisfied: dias in /home/pranab/.local/lib/python3.10/site-packages (0.1.1)\n",
      "Requirement already satisfied: pandas>=1.5.1 in /home/pranab/.local/lib/python3.10/site-packages (from dias) (2.2.1)\n",
      "Requirement already satisfied: astor>=0.8.1 in /home/pranab/.local/lib/python3.10/site-packages (from dias) (0.8.1)\n",
      "Requirement already satisfied: python-dateutil>=2.8.2 in /home/pranab/.local/lib/python3.10/site-packages (from pandas>=1.5.1->dias) (2.9.0.post0)\n",
      "Requirement already satisfied: numpy<2,>=1.22.4 in /home/pranab/.local/lib/python3.10/site-packages (from pandas>=1.5.1->dias) (1.26.3)\n",
      "Requirement already satisfied: tzdata>=2022.7 in /home/pranab/.local/lib/python3.10/site-packages (from pandas>=1.5.1->dias) (2024.1)\n",
      "Requirement already satisfied: pytz>=2020.1 in /usr/lib/python3/dist-packages (from pandas>=1.5.1->dias) (2022.1)\n",
      "Requirement already satisfied: six>=1.5 in /usr/lib/python3/dist-packages (from python-dateutil>=2.8.2->pandas>=1.5.1->dias) (1.16.0)\n",
      "Note: you may need to restart the kernel to use updated packages.\n"
     ]
    }
   ],
   "source": [
    "pip install dias"
   ]
  },
  {
   "cell_type": "code",
   "execution_count": 3,
   "id": "9d7ade77",
   "metadata": {},
   "outputs": [],
   "source": [
    "import pandas as pd\n",
    "import dias.rewriter\n",
    "import numpy as np"
   ]
  },
  {
   "cell_type": "code",
   "execution_count": 4,
   "id": "cfa07c9b",
   "metadata": {},
   "outputs": [
    {
     "ename": "NameError",
     "evalue": "name 'data' is not defined",
     "output_type": "error",
     "traceback": [
      "\u001b[0;31m---------------------------------------------------------------------------\u001b[0m",
      "\u001b[0;31mNameError\u001b[0m                                 Traceback (most recent call last)",
      "\u001b[0;32m/tmp/ipykernel_112665/2728229883.py\u001b[0m in \u001b[0;36m<module>\u001b[0;34m\u001b[0m\n\u001b[0;32m----> 1\u001b[0;31m \u001b[0mdf\u001b[0m \u001b[0;34m=\u001b[0m \u001b[0mpd\u001b[0m\u001b[0;34m.\u001b[0m\u001b[0mread_csv\u001b[0m\u001b[0;34m(\u001b[0m\u001b[0mdata\u001b[0m\u001b[0;34m.\u001b[0m\u001b[0mcsv\u001b[0m\u001b[0;34m)\u001b[0m\u001b[0;34m\u001b[0m\u001b[0;34m\u001b[0m\u001b[0m\n\u001b[0m",
      "\u001b[0;31mNameError\u001b[0m: name 'data' is not defined"
     ]
    }
   ],
   "source": [
    "df = pd.read_csv(data.csv)"
   ]
  },
  {
   "cell_type": "code",
   "execution_count": null,
   "id": "11084837",
   "metadata": {},
   "outputs": [],
   "source": []
  }
 ],
 "metadata": {
  "kernelspec": {
   "display_name": "Python 3 (ipykernel)",
   "language": "python",
   "name": "python3"
  },
  "language_info": {
   "codemirror_mode": {
    "name": "ipython",
    "version": 3
   },
   "file_extension": ".py",
   "mimetype": "text/x-python",
   "name": "python",
   "nbconvert_exporter": "python",
   "pygments_lexer": "ipython3",
   "version": "3.10.12"
  }
 },
 "nbformat": 4,
 "nbformat_minor": 5
}
